<?xml version="1.0" ?>
<!-- =================================================================================== -->
<!-- |    This document was autogenerated by xacro from centauro.urdf.xacro            | -->
<!-- |    EDITING THIS FILE BY HAND IS NOT RECOMMENDED                                 | -->
<!-- =================================================================================== -->
<robot name="centauro">
  <!-- none, ball, dagana_fixed, dagana -->
  <!-- 
  ROS urdf definition of the CENTAURO humanoid robot by Istituto Italiano di Tecnologia
  
-->
  <!-- scaling facto for available peack torque link side, from 0 to 1 -->
  <material name="black">
    <color rgba="0.4 0.4 0.4 1"/>
  </material>
  <material name="dark">
    <color rgba="0.1 0.1 0.1 1"/>
  </material>
  <material name="dark_grey">
    <color rgba="0.2 0.2 0.2 1"/>
  </material>
  <!-- Note: the "23" suffix denotes the new bigger-size wheel -->
  <!-- ??? -->
  <!-- ??? -->
  <!-- Origin -->
  <!-- <xacro:property name="hip_yaw_lower" value="${[-2.827,-2.583, -2.583 ,-2.827]}"/>
<xacro:property name="hip_yaw_upper" value="${[ 2.583, 2.827,  2.827 , 2.583]}"/> -->
  <link name="base_link"/>
  <link name="pelvis">
    <inertial>
      <origin xyz="0.010310423 0.0034907373000000004 0.057233845000000005"/>
      <mass value="18.845851"/>
      <inertia ixx="0.8762753299999999" ixy="0.022209997" ixz="-0.0061989843" iyy="1.6329654999999998" iyz="0.004551487199999999" izz="1.9611303"/>
    </inertial>
    <visual>
      <origin rpy="0.0 0.0 0.0" xyz="0.0 0 0.0"/>
      <geometry>
        <mesh filename="package://centauro_urdf/meshes/v2/pelvis.stl" scale="0.001 0.001 0.001"/>
      </geometry>
    </visual>
    <collision>
      <origin rpy="0.0 0.0 0.0" xyz="0.0 0 0.0"/>
      <geometry>
        <mesh filename="package://centauro_urdf/meshes/simple/pelvis.stl" scale="0.001 0.001 0.001"/>
      </geometry>
    </collision>
  </link>
  <link name="imu_link"/>
  <joint name="imu_joint" type="fixed">
    <parent link="pelvis"/>
    <origin rpy="0.0 0.0 0.0" xyz="0.248316 0.0 0.015"/>
    <child link="imu_link"/>
  </joint>
  <joint name="base_joint" type="revolute">
    <axis xyz="1 0 0"/>  <!-- Roll around x-axis -->
    <limit lower="-1.57" upper="1.57" effort="0" velocity="0.5"/>
    <parent link="base_link"/>
    <child link="pelvis"/>
    <origin rpy="0 0 0" xyz="0 0 0"/>
  </joint>
  <!-- ************ Control frames ************ -->

</robot>

