<?xml version="1.0" ?>
<!-- =================================================================================== -->
<!-- |    This document was autogenerated by xacro from centauro.urdf.xacro            | -->
<!-- |    EDITING THIS FILE BY HAND IS NOT RECOMMENDED                                 | -->
<!-- =================================================================================== -->
<robot name="centauro">
  <!-- none, ball, dagana_fixed, dagana -->
  <!-- 
  ROS urdf definition of the CENTAURO humanoid robot by Istituto Italiano di Tecnologia
  
-->
  <!-- scaling facto for available peack torque link side, from 0 to 1 -->
  <material name="black">
    <color rgba="0.4 0.4 0.4 1"/>
  </material>
  <material name="dark">
    <color rgba="0.1 0.1 0.1 1"/>
  </material>
  <material name="dark_grey">
    <color rgba="0.2 0.2 0.2 1"/>
  </material>
  <!-- Note: the "23" suffix denotes the new bigger-size wheel -->
  <!-- ??? -->
  <!-- ??? -->
  <!-- Origin -->
  <!-- <xacro:property name="hip_yaw_lower" value="${[-2.827,-2.583, -2.583 ,-2.827]}"/>
<xacro:property name="hip_yaw_upper" value="${[ 2.583, 2.827,  2.827 , 2.583]}"/> -->
  <link name="base_link"/>
  <link name="pelvis">
    <inertial>
      <origin xyz="0.010310423 0.0034907373000000004 0.057233845000000005"/>
      <mass value="18.845851"/>
      <inertia ixx="0.8762753299999999" ixy="0.022209997" ixz="-0.0061989843" iyy="1.6329654999999998" iyz="0.004551487199999999" izz="1.9611303"/>
    </inertial>
    <visual>
      <origin rpy="0.0 0.0 0.0" xyz="0.0 0 0.0"/>
      <geometry>
        <mesh filename="package://centauro_urdf/meshes/v2/pelvis.stl" scale="0.001 0.001 0.001"/>
      </geometry>
    </visual>
    <collision>
      <origin rpy="0.0 0.0 0.0" xyz="0.0 0 0.0"/>
      <geometry>
        <mesh filename="package://centauro_urdf/meshes/simple/pelvis.stl" scale="0.001 0.001 0.001"/>
      </geometry>
    </collision>
  </link>
  <link name="imu_link"/>
  <joint name="imu_joint" type="fixed">
    <parent link="pelvis"/>
    <origin rpy="0.0 0.0 0.0" xyz="0.248316 0.0 0.015"/>
    <child link="imu_link"/>
  </joint>
  <joint name="base_joint" type="fixed">
    <parent link="pelvis"/>
    <child link="base_link"/>
    <origin rpy="0 0 0" xyz="0 0 0"/>
  </joint>
  <!-- torso links -->
  <link name="torso_2">
    <inertial>
      <origin xyz="-0.019497794 0.0045317835 0.13768283"/>
      <mass value="12.553731"/>
      <inertia ixx="0.063643392" ixy="8.939e-05" ixz="-0.00086873" iyy="0.02680235" iyz="-4.657e-05" izz="0.04743015"/>
    </inertial>
    <visual>
      <origin rpy="0.0 0.0 0.0" xyz="0.0 0 0.0"/>
      <geometry>
        <mesh filename="package://centauro_urdf/meshes/link1_no_head.stl" scale="0.001 0.001 0.001"/>
      </geometry>
    </visual>
    <collision>
      <origin rpy="0.0 0.0 0.0" xyz="0.0 0 0.0"/>
      <geometry>
        <mesh filename="package://centauro_urdf/meshes/simple/link1_no_head.stl" scale="0.001 0.001 0.001"/>
      </geometry>
    </collision>
  </link>
  <!-- /torso links -->
  <!-- torso joints -->
  <joint name="torso_yaw" type="revolute">
    <parent link="pelvis"/>
    <origin xyz="0.2 0.0 0.256"/>
    <child link="torso_2"/>
    <axis xyz="0 0 1"/>
    <limit effort="147" lower="-2.618" upper="2.618" velocity="5.7"/>
    <!-- TODO -->
  </joint>
  <!-- /torso joints -->
  <!-- /macro arms -->
  <!-- LINKS -->
  <!-- shoulder yaw-roll-->
  <link name="arm1_1">
    <inertial>
      <origin xyz="-0.0074457212 0.03410796 0.00010978102"/>
      <mass value="1.9628675"/>
      <inertia ixx="0.0053547717" ixy="0.00036428926" ixz="1.5089568e-05" iyy="0.0033923328" iyz="5.5692312e-05" izz="0.0068921413"/>
    </inertial>
    <visual>
      <origin rpy="0.0 0.0 0.0" xyz="0.0 0.0 0.0"/>
      <geometry>
        <mesh filename="package://centauro_urdf/meshes/ShoulderPitch.STL" scale="0.001 -0.001 0.001"/>
      </geometry>
      <material name="dark_grey"/>
    </visual>
    <collision>
      <origin rpy="0.0 0.0 0.0" xyz="0.0 0.0 0.0"/>
      <geometry>
        <mesh filename="package://centauro_urdf/meshes/simple/ShoulderPitch.STL" scale="0.001 -0.001 0.001"/>
      </geometry>
    </collision>
  </link>
  <!-- shoulder yaw-roll-->
  <!-- shoulder roll-pitch-->
  <link name="arm1_2">
    <inertial>
      <origin xyz="0.058142302 5.7450803e-05 -0.077477683"/>
      <mass value="1.8595811"/>
      <inertia ixx="0.013776643" ixy="3.7788675e-05" ixz="0.0037690171" iyy="0.015677464" iyz="-9.4893549e-06" izz="0.0046317657"/>
    </inertial>
    <visual>
      <origin rpy="0.0 0.0 0.0" xyz="0.0 0.0 0.0"/>
      <geometry>
        <mesh filename="package://centauro_urdf/meshes/ShoulderRoll.STL" scale="0.001 -0.001 0.001"/>
      </geometry>
    </visual>
    <collision>
      <origin rpy="0.0 0.0 0.0" xyz="0.0 0.0 0.0"/>
      <geometry>
        <mesh filename="package://centauro_urdf/meshes/simple/ShoulderRoll.STL" scale="0.001 -0.001 0.001"/>
      </geometry>
    </collision>
  </link>
  <!-- shoulder roll-pitch-->
  <!-- shoulder-elbow -->
  <link name="arm1_3">
    <inertial>
      <origin xyz="0.014625194 0.0008172672 -0.028333545"/>
      <mass value="1.6678109"/>
      <inertia ixx="0.0064480435" ixy="-0.00015639093" ixz="0.0012205359" iyy="0.0073372077" iyz="8.9941532e-05" izz="0.0036738448"/>
    </inertial>
    <visual>
      <origin rpy="0.0 0.0 0.0" xyz="0.0 0.0 0.0"/>
      <geometry>
        <mesh filename="package://centauro_urdf/meshes/ShoulderYaw.STL" scale="0.001 -0.001 0.001"/>
      </geometry>
      <material name="dark_grey"/>
    </visual>
    <collision>
      <origin rpy="0.0 0.0 0.0" xyz="0.0 0.0 0.0"/>
      <geometry>
        <mesh filename="package://centauro_urdf/meshes/simple/ShoulderYaw.STL" scale="0.001 -0.001 0.001"/>
      </geometry>
    </collision>
  </link>
  <!-- /shoulder-elbow -->
  <!-- elbow yaw-pitch -->
  <link name="arm1_4">
    <inertial>
      <origin xyz="-0.0076833067 -0.040302205 -0.043492779"/>
      <mass value="1.3157289"/>
      <inertia ixx="0.004330394" ixy="-0.00011737391" ixz="-0.00041923199" iyy="0.0038539919" iyz="-0.00079573038" izz="0.0017594689"/>
    </inertial>
    <visual>
      <origin rpy="0.0 0.0 0.0" xyz="0.0 0.0 0.0"/>
      <geometry>
        <mesh filename="package://centauro_urdf/meshes/Elbow.STL" scale="0.001 -0.001 0.001"/>
      </geometry>
    </visual>
    <collision>
      <origin rpy="0.0 0.0 0.0" xyz="0.0 0.0 0.0"/>
      <geometry>
        <mesh filename="package://centauro_urdf/meshes/simple/Elbow.STL" scale="0.001 -0.001 0.001"/>
      </geometry>
    </collision>
  </link>
  <!-- /elbow yaw-pitch -->
  <!-- elbow-wrist -->
  <link name="arm1_5">
    <inertial>
      <origin xyz="-0.00011079615 0.011590836 -0.07816026"/>
      <mass value="1.4908547"/>
      <inertia ixx="0.0085692128" ixy="1.7856252e-05" ixz="1.9379365e-05" iyy="0.0077454159" iyz="-0.00032860094" izz="0.0027441921"/>
    </inertial>
    <visual>
      <origin rpy="0.0 0.0 0.0" xyz="0.0 0.0 0.0"/>
      <geometry>
        <mesh filename="package://centauro_urdf/meshes/Forearm.STL" scale="0.001 -0.001 0.001"/>
      </geometry>
      <material name="dark_grey"/>
    </visual>
    <collision>
      <origin rpy="0.0 0.0 0.0" xyz="0.0 0.0 0.0"/>
      <geometry>
        <mesh filename="package://centauro_urdf/meshes/simple/Forearm.STL" scale="0.001 -0.001 0.001"/>
      </geometry>
    </collision>
  </link>
  <!-- /elbow-wrist -->
  <!-- wrist yaw-pitch -->
  <link name="arm1_6">
    <inertial>
      <origin xyz="-4.6502396e-06 -0.038014094 -0.069926878"/>
      <mass value="1.1263612"/>
      <inertia ixx="0.0051871784" ixy="2.724437e-05" ixz="2.2833496e-06" iyy="0.0048037789" iyz="-0.00072165653" izz="0.0012771388"/>
    </inertial>
    <visual>
      <origin rpy="0.0 0.0 0.0" xyz="0.0 0.0 0.0"/>
      <geometry>
        <mesh filename="package://centauro_urdf/meshes/wrist_pitch_right.stl" scale="0.001 -0.001 0.001"/>
      </geometry>
    </visual>
    <collision>
      <origin rpy="0.0 0.0 0.0" xyz="0.0 0.0 0.0"/>
      <geometry>
        <mesh filename="package://centauro_urdf/meshes/simple/wrist_pitch_right.stl" scale="0.001 -0.001 0.001"/>
      </geometry>
    </collision>
  </link>
  <!-- /wrist yaw-pitch -->
  <!-- <link name="arm${arm_num}_7">
      <inertial>
         <origin xyz="${Wrist_3_x} ${rot*Wrist_3_y} ${Wrist_3_z}"/>
         <mass value="${Wrist_3_mass}"/>
         <inertia ixx="${Wrist_3_xx}" ixy="${rot*Wrist_3_xy}" ixz="${Wrist_3_xz}" iyy="${Wrist_3_yy}" iyz="${rot*Wrist_3_yz}" izz="${Wrist_3_zz}"/>
      </inertial>

      <visual>
         <origin xyz="0.0 0.0 0.0"  rpy="0.0 0.0 0.0"/>
   <geometry>
      <mesh filename="package://centauro_urdf/meshes/ForearmYaw.STL" scale="0.001 ${-rot*0.001} 0.001" />
   </geometry>
         <material name="dark_grey"/>
      </visual>

      <collision>
         <origin xyz="0.0 0.0 0.0"  rpy="0.0 0.0 0.0"/>
   <geometry>
      <mesh filename="package://centauro_urdf/meshes/simple/ForearmYaw.STL" scale="0.001 ${-rot*0.001} 0.001" />
   </geometry>
      </collision>
   </link> -->
  <!-- /LINKS -->
  <!-- JOINTS -->
  <!-- shoulder yaw -->
  <joint name="j_arm1_1" type="revolute">
    <parent link="torso_2"/>
    <child link="arm1_1"/>
    <origin rpy="0.174533 0.0 -0.5235988" xyz="0.0457475 0.169137 0.116626"/>
    <axis xyz="0 1 0"/>
    <limit effort="147.0" lower="-3.312" upper="1.615" velocity="3.86"/>
  </joint>
  <!-- /shoulder yaw -->
  <!-- shoulder roll -->
  <joint name="j_arm1_2" type="revolute">
    <parent link="arm1_1"/>
    <child link="arm1_2"/>
    <origin rpy="-0.1745327 0.0 0.0" xyz="-0.09015 0.062 0.0"/>
    <axis xyz="1 0 0"/>
    <limit effort="147.0" lower="0.02" upper="3.431" velocity="3.86"/>
  </joint>
  <!-- /shoulder roll -->
  <!-- shoulder pitch-->
  <joint name="j_arm1_3" type="revolute">
    <parent link="arm1_2"/>
    <child link="arm1_3"/>
    <origin xyz="0.09015 0.0 -0.21815"/>
    <axis xyz="0 0 1"/>
    <limit effort="147.0" lower="-2.552" upper="2.566" velocity="6.06"/>
  </joint>
  <!-- /shoulder pitch -->
  <!-- elbow yaw -->
  <joint name="j_arm1_4" type="revolute">
    <parent link="arm1_3"/>
    <child link="arm1_4"/>
    <origin xyz="0.045 0.05515 -0.074"/>
    <axis xyz="0 1 0"/>
    <limit effort="147.0" lower="-2.465" upper="0.28" velocity="6.06"/>
  </joint>
  <!-- /elbow yaw -->
  <!-- elbow pitch-->
  <joint name="j_arm1_5" type="revolute">
    <parent link="arm1_4"/>
    <child link="arm1_5"/>
    <origin xyz="-0.015 -0.05515 -0.095"/>
    <axis xyz="0 0 1"/>
    <limit effort="55.0" lower="-2.569" upper="2.562" velocity="11.72"/>
  </joint>
  <!-- /elbow pitch-->
  <!-- wrist yaw-->
  <joint name="j_arm1_6" type="revolute">
    <parent link="arm1_5"/>
    <child link="arm1_6"/>
    <origin xyz="0.0 0.049 -0.156"/>
    <axis xyz="0 1 0"/>
    <limit effort="55.0" lower="-1.529" upper="1.509" velocity="11.72"/>
  </joint>
  <!-- /wrist yaw-->
  <!-- wrist pitch-->
  <!-- <joint name="j_arm${arm_num}_7" type="fixed">
      <parent link="arm${arm_num}_6"/>
      <child link="arm${arm_num}_7"/>
      <origin xyz="${Wrist_3_Ox} ${rot*Wrist_3_Oy} ${Wrist_3_Oz}"/>
      <axis xyz="0 0 1"/>
      <limit lower="${j_arm_7_lower[arm_num-1]}" upper="${j_arm_7_upper[arm_num-1]}" effort="${j_arm_7_torque[arm_num-1]}" velocity="${j_arm_7_velocity[arm_num-1]}"/>
   </joint> -->
  <!-- wrist pitch-->
  <!-- force-troque sensor -->
  <!-- end-effector -->
  <!-- wrist pitch-->
  <!-- <joint name="j_ft_${arm_num}" type="fixed">
      <parent link="arm${arm_num}_7"/>
      <child link="ft_arm${arm_num}"/>
      <origin xyz="${Ft_arm_Ox} ${Ft_arm_Oy} ${Ft_arm_Oz}" rpy="${Ft_arm_roll} ${Ft_arm_pitch} ${Ft_arm_yaw}" />
      <axis xyz="0 0 1"/>
      <limit lower="0.0" upper="0.0" effort="0" velocity="0"/>
   </joint> -->
  <!-- wrist pitch-->
  <!-- <link name="ft_arm${arm_num}">
      <inertial>
         <origin xyz="${Ft_arm_x} ${rot*Ft_arm_y} ${Ft_arm_z}"/>
         <mass value="${Ft_arm_mass}"/>
         <inertia ixx="${Ft_arm_xx}" ixy="${rot*Ft_arm_xy}" ixz="${Ft_arm_xz}" iyy="${Ft_arm_yy}" iyz="${rot*Ft_arm_yz}" izz="${Ft_arm_zz}"/>
      </inertial> -->
  <!--visual>
         <origin xyz="0.0 0.0 0.0"  rpy="${PI} 0.0 0.0"/>
   <geometry>
      <mesh filename="package://centauro_urdf/meshes/Wrist.STL" scale="0.001 ${-rot*0.001} 0.001" />
   </geometry>
      </visual-->
  <!--collision>
         <origin xyz="0.0 0.0 0.0"  rpy="${PI} 0.0 0.0"/>
   <geometry>
      <mesh filename="package://centauro_urdf/meshes/simple/Wrist.STL" scale="0.001 ${-rot*0.001} 0.001" />
   </geometry>
      </collision-->
  <!-- </link> -->
  <!-- LINKS -->
  <!-- shoulder yaw-roll-->
  <link name="arm2_1">
    <inertial>
      <origin xyz="-0.0074457212 -0.03410796 0.00010978102"/>
      <mass value="1.9628675"/>
      <inertia ixx="0.0053547717" ixy="-0.00036428926" ixz="1.5089568e-05" iyy="0.0033923328" iyz="-5.5692312e-05" izz="0.0068921413"/>
    </inertial>
    <visual>
      <origin rpy="0.0 0.0 0.0" xyz="0.0 0.0 0.0"/>
      <geometry>
        <mesh filename="package://centauro_urdf/meshes/ShoulderPitch.STL" scale="0.001 0.001 0.001"/>
      </geometry>
      <material name="dark_grey"/>
    </visual>
    <collision>
      <origin rpy="0.0 0.0 0.0" xyz="0.0 0.0 0.0"/>
      <geometry>
        <mesh filename="package://centauro_urdf/meshes/simple/ShoulderPitch.STL" scale="0.001 0.001 0.001"/>
      </geometry>
    </collision>
  </link>
  <!-- shoulder yaw-roll-->
  <!-- shoulder roll-pitch-->
  <link name="arm2_2">
    <inertial>
      <origin xyz="0.058142302 -5.7450803e-05 -0.077477683"/>
      <mass value="1.8595811"/>
      <inertia ixx="0.013776643" ixy="-3.7788675e-05" ixz="0.0037690171" iyy="0.015677464" iyz="9.4893549e-06" izz="0.0046317657"/>
    </inertial>
    <visual>
      <origin rpy="0.0 0.0 0.0" xyz="0.0 0.0 0.0"/>
      <geometry>
        <mesh filename="package://centauro_urdf/meshes/ShoulderRoll.STL" scale="0.001 0.001 0.001"/>
      </geometry>
    </visual>
    <collision>
      <origin rpy="0.0 0.0 0.0" xyz="0.0 0.0 0.0"/>
      <geometry>
        <mesh filename="package://centauro_urdf/meshes/simple/ShoulderRoll.STL" scale="0.001 0.001 0.001"/>
      </geometry>
    </collision>
  </link>
  <!-- shoulder roll-pitch-->
  <!-- shoulder-elbow -->
  <link name="arm2_3">
    <inertial>
      <origin xyz="0.014625194 -0.0008172672 -0.028333545"/>
      <mass value="1.6678109"/>
      <inertia ixx="0.0064480435" ixy="0.00015639093" ixz="0.0012205359" iyy="0.0073372077" iyz="-8.9941532e-05" izz="0.0036738448"/>
    </inertial>
    <visual>
      <origin rpy="0.0 0.0 0.0" xyz="0.0 0.0 0.0"/>
      <geometry>
        <mesh filename="package://centauro_urdf/meshes/ShoulderYaw.STL" scale="0.001 0.001 0.001"/>
      </geometry>
      <material name="dark_grey"/>
    </visual>
    <collision>
      <origin rpy="0.0 0.0 0.0" xyz="0.0 0.0 0.0"/>
      <geometry>
        <mesh filename="package://centauro_urdf/meshes/simple/ShoulderYaw.STL" scale="0.001 0.001 0.001"/>
      </geometry>
    </collision>
  </link>
  <!-- /shoulder-elbow -->
  <!-- elbow yaw-pitch -->
  <link name="arm2_4">
    <inertial>
      <origin xyz="-0.0076833067 0.040302205 -0.043492779"/>
      <mass value="1.3157289"/>
      <inertia ixx="0.004330394" ixy="0.00011737391" ixz="-0.00041923199" iyy="0.0038539919" iyz="0.00079573038" izz="0.0017594689"/>
    </inertial>
    <visual>
      <origin rpy="0.0 0.0 0.0" xyz="0.0 0.0 0.0"/>
      <geometry>
        <mesh filename="package://centauro_urdf/meshes/Elbow.STL" scale="0.001 0.001 0.001"/>
      </geometry>
    </visual>
    <collision>
      <origin rpy="0.0 0.0 0.0" xyz="0.0 0.0 0.0"/>
      <geometry>
        <mesh filename="package://centauro_urdf/meshes/simple/Elbow.STL" scale="0.001 0.001 0.001"/>
      </geometry>
    </collision>
  </link>
  <!-- /elbow yaw-pitch -->
  <!-- elbow-wrist -->
  <link name="arm2_5">
    <inertial>
      <origin xyz="-0.00011079615 -0.011590836 -0.07816026"/>
      <mass value="1.4908547"/>
      <inertia ixx="0.0085692128" ixy="-1.7856252e-05" ixz="1.9379365e-05" iyy="0.0077454159" iyz="0.00032860094" izz="0.0027441921"/>
    </inertial>
    <visual>
      <origin rpy="0.0 0.0 0.0" xyz="0.0 0.0 0.0"/>
      <geometry>
        <mesh filename="package://centauro_urdf/meshes/Forearm.STL" scale="0.001 0.001 0.001"/>
      </geometry>
      <material name="dark_grey"/>
    </visual>
    <collision>
      <origin rpy="0.0 0.0 0.0" xyz="0.0 0.0 0.0"/>
      <geometry>
        <mesh filename="package://centauro_urdf/meshes/simple/Forearm.STL" scale="0.001 0.001 0.001"/>
      </geometry>
    </collision>
  </link>
  <!-- /elbow-wrist -->
  <!-- wrist yaw-pitch -->
  <link name="arm2_6">
    <inertial>
      <origin xyz="-4.6502396e-06 0.038014094 -0.069926878"/>
      <mass value="1.1263612"/>
      <inertia ixx="0.0051871784" ixy="-2.724437e-05" ixz="2.2833496e-06" iyy="0.0048037789" iyz="0.00072165653" izz="0.0012771388"/>
    </inertial>
    <visual>
      <origin rpy="0.0 0.0 0.0" xyz="0.0 0.0 0.0"/>
      <geometry>
        <mesh filename="package://centauro_urdf/meshes/wrist_pitch_right.stl" scale="0.001 0.001 0.001"/>
      </geometry>
    </visual>
    <collision>
      <origin rpy="0.0 0.0 0.0" xyz="0.0 0.0 0.0"/>
      <geometry>
        <mesh filename="package://centauro_urdf/meshes/simple/wrist_pitch_right.stl" scale="0.001 0.001 0.001"/>
      </geometry>
    </collision>
  </link>
  <!-- /wrist yaw-pitch -->
  <!-- <link name="arm${arm_num}_7">
      <inertial>
         <origin xyz="${Wrist_3_x} ${rot*Wrist_3_y} ${Wrist_3_z}"/>
         <mass value="${Wrist_3_mass}"/>
         <inertia ixx="${Wrist_3_xx}" ixy="${rot*Wrist_3_xy}" ixz="${Wrist_3_xz}" iyy="${Wrist_3_yy}" iyz="${rot*Wrist_3_yz}" izz="${Wrist_3_zz}"/>
      </inertial>

      <visual>
         <origin xyz="0.0 0.0 0.0"  rpy="0.0 0.0 0.0"/>
   <geometry>
      <mesh filename="package://centauro_urdf/meshes/ForearmYaw.STL" scale="0.001 ${-rot*0.001} 0.001" />
   </geometry>
         <material name="dark_grey"/>
      </visual>

      <collision>
         <origin xyz="0.0 0.0 0.0"  rpy="0.0 0.0 0.0"/>
   <geometry>
      <mesh filename="package://centauro_urdf/meshes/simple/ForearmYaw.STL" scale="0.001 ${-rot*0.001} 0.001" />
   </geometry>
      </collision>
   </link> -->
  <!-- /LINKS -->
  <!-- JOINTS -->
  <!-- shoulder yaw -->
  <joint name="j_arm2_1" type="revolute">
    <parent link="torso_2"/>
    <child link="arm2_1"/>
    <origin rpy="-0.174533 0.0 0.5235988" xyz="0.0457475 -0.169137 0.116626"/>
    <axis xyz="0 1 0"/>
    <limit effort="147.0" lower="-3.3458" upper="1.6012" velocity="3.86"/>
  </joint>
  <!-- /shoulder yaw -->
  <!-- shoulder roll -->
  <joint name="j_arm2_2" type="revolute">
    <parent link="arm2_1"/>
    <child link="arm2_2"/>
    <origin rpy="0.1745327 0.0 0.0" xyz="-0.09015 -0.062 0.0"/>
    <axis xyz="1 0 0"/>
    <limit effort="147.0" lower="-3.4258" upper="-0.0138" velocity="3.86"/>
  </joint>
  <!-- /shoulder roll -->
  <!-- shoulder pitch-->
  <joint name="j_arm2_3" type="revolute">
    <parent link="arm2_2"/>
    <child link="arm2_3"/>
    <origin xyz="0.09015 0.0 -0.21815"/>
    <axis xyz="0 0 1"/>
    <limit effort="147.0" lower="-2.5614" upper="2.5606" velocity="6.06"/>
  </joint>
  <!-- /shoulder pitch -->
  <!-- elbow yaw -->
  <joint name="j_arm2_4" type="revolute">
    <parent link="arm2_3"/>
    <child link="arm2_4"/>
    <origin xyz="0.045 -0.05515 -0.074"/>
    <axis xyz="0 1 0"/>
    <limit effort="147.0" lower="-2.4794" upper="0.2886" velocity="6.06"/>
  </joint>
  <!-- /elbow yaw -->
  <!-- elbow pitch-->
  <joint name="j_arm2_5" type="revolute">
    <parent link="arm2_4"/>
    <child link="arm2_5"/>
    <origin xyz="-0.015 0.05515 -0.095"/>
    <axis xyz="0 0 1"/>
    <limit effort="55.0" lower="-2.5394" upper="2.5546" velocity="11.72"/>
  </joint>
  <!-- /elbow pitch-->
  <!-- wrist yaw-->
  <joint name="j_arm2_6" type="revolute">
    <parent link="arm2_5"/>
    <child link="arm2_6"/>
    <origin xyz="0.0 -0.049 -0.156"/>
    <axis xyz="0 1 0"/>
    <limit effort="55.0" lower="-1.5154" upper="1.5156" velocity="11.72"/>
  </joint>
  <!-- /wrist yaw-->
  <!-- wrist pitch-->
  <!-- <joint name="j_arm${arm_num}_7" type="fixed">
      <parent link="arm${arm_num}_6"/>
      <child link="arm${arm_num}_7"/>
      <origin xyz="${Wrist_3_Ox} ${rot*Wrist_3_Oy} ${Wrist_3_Oz}"/>
      <axis xyz="0 0 1"/>
      <limit lower="${j_arm_7_lower[arm_num-1]}" upper="${j_arm_7_upper[arm_num-1]}" effort="${j_arm_7_torque[arm_num-1]}" velocity="${j_arm_7_velocity[arm_num-1]}"/>
   </joint> -->
  <!-- wrist pitch-->
  <!-- force-troque sensor -->
  <!-- end-effector -->
  <!-- wrist pitch-->
  <!-- <joint name="j_ft_${arm_num}" type="fixed">
      <parent link="arm${arm_num}_7"/>
      <child link="ft_arm${arm_num}"/>
      <origin xyz="${Ft_arm_Ox} ${Ft_arm_Oy} ${Ft_arm_Oz}" rpy="${Ft_arm_roll} ${Ft_arm_pitch} ${Ft_arm_yaw}" />
      <axis xyz="0 0 1"/>
      <limit lower="0.0" upper="0.0" effort="0" velocity="0"/>
   </joint> -->
  <!-- wrist pitch-->
  <!-- <link name="ft_arm${arm_num}">
      <inertial>
         <origin xyz="${Ft_arm_x} ${rot*Ft_arm_y} ${Ft_arm_z}"/>
         <mass value="${Ft_arm_mass}"/>
         <inertia ixx="${Ft_arm_xx}" ixy="${rot*Ft_arm_xy}" ixz="${Ft_arm_xz}" iyy="${Ft_arm_yy}" iyz="${rot*Ft_arm_yz}" izz="${Ft_arm_zz}"/>
      </inertial> -->
  <!--visual>
         <origin xyz="0.0 0.0 0.0"  rpy="${PI} 0.0 0.0"/>
   <geometry>
      <mesh filename="package://centauro_urdf/meshes/Wrist.STL" scale="0.001 ${-rot*0.001} 0.001" />
   </geometry>
      </visual-->
  <!--collision>
         <origin xyz="0.0 0.0 0.0"  rpy="${PI} 0.0 0.0"/>
   <geometry>
      <mesh filename="package://centauro_urdf/meshes/simple/Wrist.STL" scale="0.001 ${-rot*0.001} 0.001" />
   </geometry>
      </collision-->
  <!-- </link> -->
  <link name="ball1">
    <inertial>
      <origin rpy="0 0 0" xyz="-1.0072498e-05 3.7590658e-05 0.019772332"/>
      <mass value="1.27"/>
      <inertia ixx="0.0023061092" ixy="2.9181758e-07" ixz="-2.1246683999999997e-07" iyy="0.0023053155000000002" iyz="7.9290978e-07" izz="0.0030675615999999997"/>
    </inertial>
    <visual>
      <origin rpy="0.0 0.0 0.0" xyz="0.0 0.0 0.0"/>
      <geometry name="ball1_visual">
        <mesh filename="package://centauro_urdf/meshes/BallHand.stl" scale="0.001 0.001 0.001"/>
      </geometry>
      <material name="dark_grey"/>
    </visual>
    <collision>
      <origin rpy="0.0 0.0 0.0" xyz="0.0 0.0 0.0"/>
      <geometry name="ball1_collision">
        <mesh filename="package://centauro_urdf/meshes/simple/BallHand.stl" scale="0.001 0.001 0.001"/>
      </geometry>
    </collision>
  </link>
  <link name="ball1_tip"/>
  <joint name="j_arm1_8" type="fixed">
    <parent link="arm1_6"/>
    <child link="ball1"/>
    <origin rpy="0. 0. 0." xyz="0. -0.05 -0.105"/>
  </joint>
  <joint name="j_ball1_tip" type="fixed">
    <parent link="ball1"/>
    <child link="ball1_tip"/>
    <origin rpy="0 0 0" xyz="0 0 -0.07"/>
  </joint>
  <!-- add armX_8 link for legacy reasons (same as ballX) -->
  <joint name="j_ball1_fixed" type="fixed">
    <parent link="ball1"/>
    <child link="arm1_8"/>
  </joint>
  <link name="arm1_8">
    <inertial>
      <mass value="0"/>
      <inertia ixx="0" ixy="0" ixz="0" iyy="0" iyz="0" izz="0"/>
    </inertial>
  </link>
  <link name="ball2">
    <inertial>
      <origin rpy="0 0 0" xyz="-1.0072498e-05 3.7590658e-05 0.019772332"/>
      <mass value="1.27"/>
      <inertia ixx="0.0023061092" ixy="2.9181758e-07" ixz="-2.1246683999999997e-07" iyy="0.0023053155000000002" iyz="7.9290978e-07" izz="0.0030675615999999997"/>
    </inertial>
    <visual>
      <origin rpy="0.0 0.0 0.0" xyz="0.0 0.0 0.0"/>
      <geometry name="ball2_visual">
        <mesh filename="package://centauro_urdf/meshes/BallHand.stl" scale="0.001 0.001 0.001"/>
      </geometry>
      <material name="dark_grey"/>
    </visual>
    <collision>
      <origin rpy="0.0 0.0 0.0" xyz="0.0 0.0 0.0"/>
      <geometry name="ball2_collision">
        <mesh filename="package://centauro_urdf/meshes/simple/BallHand.stl" scale="0.001 0.001 0.001"/>
      </geometry>
    </collision>
  </link>
  <link name="ball2_tip"/>
  <joint name="j_arm2_8" type="fixed">
    <parent link="arm2_6"/>
    <child link="ball2"/>
    <origin rpy="0. 0. 0." xyz="0. 0.05 -0.105"/>
  </joint>
  <joint name="j_ball2_tip" type="fixed">
    <parent link="ball2"/>
    <child link="ball2_tip"/>
    <origin rpy="0 0 0" xyz="0 0 -0.07"/>
  </joint>
  <!-- add armX_8 link for legacy reasons (same as ballX) -->
  <joint name="j_ball2_fixed" type="fixed">
    <parent link="ball2"/>
    <child link="arm2_8"/>
  </joint>
  <link name="arm2_8">
    <inertial>
      <mass value="0"/>
      <inertia ixx="0" ixy="0" ixz="0" iyy="0" iyz="0" izz="0"/>
    </inertial>
  </link>
  <!-- LINKS -->
  <link name="neck_1">
    <inertial>
      <origin xyz="0 0 0"/>
      <mass value="0.33878686"/>
      <!-- MASS/INERTIA TO DO -->
      <inertia ixx="0.0003718568" ixy="-9.42983e-05" ixz="-2.80644e-05" iyy="0.0001886879" iyz="-1.54534e-05" izz="0.0005023443"/>
    </inertial>
    <visual>
      <origin rpy="0.0 0.0 0.0" xyz="0.0 0 0.0"/>
      <geometry>
        <mesh filename="package://centauro_urdf/meshes/head-base_mesh.stl" scale="0.001 0.001 0.001"/>
      </geometry>
    </visual>
    <collision>
      <origin rpy="0.0 0.0 0.0" xyz="0.0 0 0.0"/>
      <geometry>
        <mesh filename="package://centauro_urdf/meshes/simple/head-base_mesh.stl" scale="0.001 0.001 0.001"/>
      </geometry>
    </collision>
  </link>
  <link name="velodyne_motor">
    <inertial>
      <origin xyz="0 0 0"/>
      <mass value="0.33878686"/>
      <!-- MASS/INERTIA TO DO -->
      <inertia ixx="0.0003718568" ixy="-9.42983e-05" ixz="-2.80644e-05" iyy="0.0001886879" iyz="-1.54534e-05" izz="0.0005023443"/>
    </inertial>
    <visual>
      <origin rpy="0.0 0.0 0.0" xyz="0.0 0 0.0"/>
      <geometry>
        <mesh filename="package://centauro_urdf/meshes/lidar_mesh.stl" scale="0.001 0.001 0.001"/>
      </geometry>
    </visual>
    <collision>
      <origin rpy="0.0 0.0 0.0" xyz="0.0 0 0.0"/>
      <geometry>
        <mesh filename="package://centauro_urdf/meshes/simple/lidar_mesh.stl" scale="0.001 0.001 0.001"/>
      </geometry>
    </collision>
  </link>
  <link name="d435_head_motor">
    <inertial>
      <origin xyz="0 0 0"/>
      <mass value="0.33878686"/>
      <!-- MASS/INERTIA TO DO -->
      <inertia ixx="0.0003718568" ixy="-9.42983e-05" ixz="-2.80644e-05" iyy="0.0001886879" iyz="-1.54534e-05" izz="0.0005023443"/>
    </inertial>
    <visual>
      <origin rpy="0.0 0.0 0.0" xyz="0.0 0 0.0"/>
      <geometry>
        <mesh filename="package://centauro_urdf/meshes/neck-pitch_mesh.stl" scale="0.001 0.001 0.001"/>
      </geometry>
    </visual>
    <collision>
      <origin rpy="0.0 0.0 0.0" xyz="0.0 0 0.0"/>
      <geometry>
        <mesh filename="package://centauro_urdf/meshes/simple/neck-pitch_mesh.stl" scale="0.001 0.001 0.001"/>
      </geometry>
    </collision>
  </link>
  <!--JOINTS -->
  <joint name="neck_base" type="fixed">
    <parent link="torso_2"/>
    <origin rpy="0 0 0" xyz="0.0030637045 0.0061607221 0.158"/>
    <child link="neck_1"/>
    <axis xyz="0 0 1"/>
  </joint>
  <joint name="velodyne_joint" type="revolute">
    <parent link="neck_1"/>
    <origin rpy="0 0 0" xyz="0.0822724 0 0.242"/>
    <child link="velodyne_motor"/>
    <axis xyz="0 -1 0"/>
    <limit effort="35" lower="-1.1" upper="1.1" velocity="5.7"/>
    <dynamics friction="10.0"/>
  </joint>
  <joint name="d435_head_joint" type="revolute">
    <parent link="neck_1"/>
    <origin rpy="0 0 0" xyz="0.06 0 0.1375"/>
    <child link="d435_head_motor"/>
    <axis xyz="0 -1 0"/>
    <limit effort="35" lower="-1.1" upper="1.1" velocity="5.7"/>
    <dynamics friction="10.0"/>
  </joint>
  <!-- camera body, with origin at bottom screw mount -->
  <joint name="D435_head_camera_joint" type="fixed">
    <origin rpy="0 0 0" xyz="0.03015 0 -0.0125"/>
    <parent link="d435_head_motor"/>
    <child link="D435_head_camera_bottom_screw_frame"/>
  </joint>
  <link name="D435_head_camera_bottom_screw_frame"/>
  <joint name="D435_head_camera_link_joint" type="fixed">
    <origin rpy="0 0 0" xyz="0 0.0175 0.0125"/>
    <parent link="D435_head_camera_bottom_screw_frame"/>
    <child link="D435_head_camera_link"/>
  </joint>
  <link name="D435_head_camera_link">
    <visual>
      <origin rpy="1.570796326795 0 1.570796326795" xyz="0.0149 -0.0175 0"/>
      <geometry>
        <!-- <box size="${d435_cam_width} ${d435_cam_height} ${d435_cam_depth}"/> -->
        <mesh filename="package://centauro_urdf/meshes/realsense/d435.dae"/>
      </geometry>
      <material name="D435_head_camera_aluminum"/>
    </visual>
    <collision>
      <origin rpy="0 0 0" xyz="0 -0.0175 0"/>
      <geometry>
        <box size="0.02505 0.09 0.025"/>
      </geometry>
    </collision>
    <inertial>
      <!-- The following are not reliable values, and should not be used for modeling -->
      <mass value="0.564"/>
      <origin xyz="0 0 0"/>
      <inertia ixx="0.003881243" ixy="0.0" ixz="0.0" iyy="0.000498940" iyz="0.0" izz="0.003879257"/>
    </inertial>
  </link>
  <joint name="velodyne_calib_base_mount_joint" type="fixed">
    <origin rpy="0.025 0.019 0" xyz="-0.01 0.02 0.06"/>
    <parent link="velodyne_motor"/>
    <child link="velodyne_calib_base_link"/>
  </joint>
  <link name="velodyne_calib_base_link">
    <inertial>
      <mass value="0.83"/>
      <origin xyz="0 0 0.03585"/>
      <inertia ixx="0.000908059425" ixy="0" ixz="0" iyy="0.000908059425" iyz="0" izz="0.0011049624"/>
    </inertial>
    <visual>
      <geometry>
        <mesh filename="package://velodyne_description/meshes/VLP16_base_1.dae"/>
      </geometry>
    </visual>
    <visual>
      <geometry>
        <mesh filename="package://velodyne_description/meshes/VLP16_base_2.dae"/>
      </geometry>
    </visual>
    <collision>
      <origin rpy="0 0 0" xyz="0 0 0.03585"/>
      <geometry>
        <cylinder length="0.0717" radius="0.0516"/>
      </geometry>
    </collision>
  </link>
  <joint name="velodyne_calib_base_scan_joint" type="fixed">
    <origin rpy="0 0 0" xyz="0 0 0.0377"/>
    <parent link="velodyne_calib_base_link"/>
    <child link="velodyne_calib"/>
  </joint>
  <link name="velodyne_calib">
    <inertial>
      <mass value="0.01"/>
      <origin xyz="0 0 0"/>
      <inertia ixx="1e-7" ixy="0" ixz="0" iyy="1e-7" iyz="0" izz="1e-7"/>
    </inertial>
    <visual>
      <origin xyz="0 0 -0.0377"/>
      <geometry>
        <mesh filename="package://velodyne_description/meshes/VLP16_scan.dae"/>
      </geometry>
    </visual>
    <collision>
      <geometry>
        <sphere radius="0"/>
      </geometry>
    </collision>
  </link>
  <!-- Gazebo requires the velodyne_gazebo_plugins package -->
  <gazebo reference="velodyne_calib">
    <sensor name="velodyne_calib-VLP16" type="ray">
      <pose>0 0 0 0 0 0</pose>
      <visualize>false</visualize>
      <update_rate>10</update_rate>
      <ray>
        <scan>
          <horizontal>
            <samples>440</samples>
            <resolution>1</resolution>
            <min_angle>-3.141592653589793</min_angle>
            <max_angle>3.141592653589793</max_angle>
          </horizontal>
          <vertical>
            <samples>16</samples>
            <resolution>1</resolution>
            <min_angle>-0.2617993877991494</min_angle>
            <max_angle> 0.2617993877991494</max_angle>
          </vertical>
        </scan>
        <range>
          <min>0.3</min>
          <max>131.0</max>
          <resolution>0.001</resolution>
        </range>
        <noise>
          <type>gaussian</type>
          <mean>0.0</mean>
          <stddev>0.0</stddev>
        </noise>
      </ray>
      <plugin filename="libgazebo_ros_velodyne_laser.so" name="gazebo_ros_laser_controller">
        <topicName>/velodyne_points</topicName>
        <frameName>velodyne_calib</frameName>
        <organize_cloud>False</organize_cloud>
        <min_range>0.9</min_range>
        <max_range>130.0</max_range>
        <gaussianNoise>0.008</gaussianNoise>
      </plugin>
    </sensor>
  </gazebo>
  <!-- camera body, with origin at bottom screw mount -->
  <joint name="D435i_camera_joint" type="fixed">
    <origin rpy="0 0.54 0" xyz="0.272 0 0.084"/>
    <parent link="pelvis"/>
    <child link="D435i_camera_bottom_screw_frame"/>
  </joint>
  <link name="D435i_camera_bottom_screw_frame"/>
  <joint name="D435i_camera_link_joint" type="fixed">
    <origin rpy="0 0.0050 -0.008" xyz="0.053 0.0 -0.035"/>
    <parent link="D435i_camera_bottom_screw_frame"/>
    <child link="D435i_camera_link"/>
  </joint>
  <link name="D435i_camera_link">
    <visual>
      <origin rpy="1.570796326795 0 1.570796326795" xyz="0.053 -0.0 0"/>
      <geometry>
        <!-- <box size="${d435_cam_width} ${d435_cam_height} ${d435_cam_depth}"/> -->
        <mesh filename="package://centauro_urdf/meshes/realsense/d435.dae"/>
      </geometry>
      <material name="D435i_camera_aluminum"/>
    </visual>
    <collision>
      <origin rpy="0 0 0" xyz="0 -0.0 0"/>
      <geometry>
        <box size="0.02505 0.09 0.025"/>
      </geometry>
    </collision>
    <inertial>
      <!-- The following are not reliable values, and should not be used for modeling -->
      <mass value="0.564"/>
      <origin xyz="0 0 0"/>
      <inertia ixx="0.003881243" ixy="0.0" ixz="0.0" iyy="0.000498940" iyz="0.0" izz="0.003879257"/>
    </inertial>
  </link>
  <!-- ************ Control frames ************ -->
</robot>

